Traceback (most recent call last):
  File "/opt/hostedtoolcache/Python/3.7.11/x64/lib/python3.7/site-packages/jupyter_cache/executors/utils.py", line 56, in single_nb_execution
    record_timing=False,
  File "/opt/hostedtoolcache/Python/3.7.11/x64/lib/python3.7/site-packages/nbclient/client.py", line 1112, in execute
    return NotebookClient(nb=nb, resources=resources, km=km, **kwargs).execute()
  File "/opt/hostedtoolcache/Python/3.7.11/x64/lib/python3.7/site-packages/nbclient/util.py", line 74, in wrapped
    return just_run(coro(*args, **kwargs))
  File "/opt/hostedtoolcache/Python/3.7.11/x64/lib/python3.7/site-packages/nbclient/util.py", line 53, in just_run
    return loop.run_until_complete(coro)
  File "/opt/hostedtoolcache/Python/3.7.11/x64/lib/python3.7/asyncio/base_events.py", line 587, in run_until_complete
    return future.result()
  File "/opt/hostedtoolcache/Python/3.7.11/x64/lib/python3.7/site-packages/nbclient/client.py", line 554, in async_execute
    cell, index, execution_count=self.code_cells_executed + 1
  File "/opt/hostedtoolcache/Python/3.7.11/x64/lib/python3.7/site-packages/nbclient/client.py", line 857, in async_execute_cell
    self._check_raise_for_error(cell, exec_reply)
  File "/opt/hostedtoolcache/Python/3.7.11/x64/lib/python3.7/site-packages/nbclient/client.py", line 760, in _check_raise_for_error
    raise CellExecutionError.from_cell_and_msg(cell, exec_reply_content)
nbclient.exceptions.CellExecutionError: An error occurred while executing the following cell:
------------------
import pvlib

df, meta = pvlib.iotools.get_bsrn(
    station='cab', start=pd.Timestamp(2018,6,1), end=pd.Timestamp(2018,8,31),
    username=BSRN_USERNAME, password=BSRN_PASSWORD)


------------------

[0;31m---------------------------------------------------------------------------[0m
[0;31merror_perm[0m                                Traceback (most recent call last)
[0;32m/opt/hostedtoolcache/Python/3.7.11/x64/lib/python3.7/site-packages/pvlib/iotools/bsrn.py[0m in [0;36mget_bsrn[0;34m(start, end, station, username, password, logical_records, local_path)[0m
[1;32m    164[0m         [0;32mtry[0m[0;34m:[0m[0;34m[0m[0;34m[0m[0m
[0;32m--> 165[0;31m             [0mftp[0m[0;34m.[0m[0mcwd[0m[0;34m([0m[0;34mf'/{station}'[0m[0;34m)[0m[0;34m[0m[0;34m[0m[0m
[0m[1;32m    166[0m         [0;32mexcept[0m [0mftplib[0m[0;34m.[0m[0merror_perm[0m [0;32mas[0m [0me[0m[0;34m:[0m[0;34m[0m[0;34m[0m[0m

[0;32m/opt/hostedtoolcache/Python/3.7.11/x64/lib/python3.7/ftplib.py[0m in [0;36mcwd[0;34m(self, dirname)[0m
[1;32m    637[0m         [0mcmd[0m [0;34m=[0m [0;34m'CWD '[0m [0;34m+[0m [0mdirname[0m[0;34m[0m[0;34m[0m[0m
[0;32m--> 638[0;31m         [0;32mreturn[0m [0mself[0m[0;34m.[0m[0mvoidcmd[0m[0;34m([0m[0mcmd[0m[0;34m)[0m[0;34m[0m[0;34m[0m[0m
[0m[1;32m    639[0m [0;34m[0m[0m

[0;32m/opt/hostedtoolcache/Python/3.7.11/x64/lib/python3.7/ftplib.py[0m in [0;36mvoidcmd[0;34m(self, cmd)[0m
[1;32m    279[0m         [0mself[0m[0;34m.[0m[0mputcmd[0m[0;34m([0m[0mcmd[0m[0;34m)[0m[0;34m[0m[0;34m[0m[0m
[0;32m--> 280[0;31m         [0;32mreturn[0m [0mself[0m[0;34m.[0m[0mvoidresp[0m[0;34m([0m[0;34m)[0m[0;34m[0m[0;34m[0m[0m
[0m[1;32m    281[0m [0;34m[0m[0m

[0;32m/opt/hostedtoolcache/Python/3.7.11/x64/lib/python3.7/ftplib.py[0m in [0;36mvoidresp[0;34m(self)[0m
[1;32m    252[0m         [0;34m"""Expect a response beginning with '2'."""[0m[0;34m[0m[0;34m[0m[0m
[0;32m--> 253[0;31m         [0mresp[0m [0;34m=[0m [0mself[0m[0;34m.[0m[0mgetresp[0m[0;34m([0m[0;34m)[0m[0;34m[0m[0;34m[0m[0m
[0m[1;32m    254[0m         [0;32mif[0m [0mresp[0m[0;34m[[0m[0;34m:[0m[0;36m1[0m[0;34m][0m [0;34m!=[0m [0;34m'2'[0m[0;34m:[0m[0;34m[0m[0;34m[0m[0m

[0;32m/opt/hostedtoolcache/Python/3.7.11/x64/lib/python3.7/ftplib.py[0m in [0;36mgetresp[0;34m(self)[0m
[1;32m    247[0m         [0;32mif[0m [0mc[0m [0;34m==[0m [0;34m'5'[0m[0;34m:[0m[0;34m[0m[0;34m[0m[0m
[0;32m--> 248[0;31m             [0;32mraise[0m [0merror_perm[0m[0;34m([0m[0mresp[0m[0;34m)[0m[0;34m[0m[0;34m[0m[0m
[0m[1;32m    249[0m         [0;32mraise[0m [0merror_proto[0m[0;34m([0m[0mresp[0m[0;34m)[0m[0;34m[0m[0;34m[0m[0m

[0;31merror_perm[0m: 530 Please login with USER and PASS.

The above exception was the direct cause of the following exception:

[0;31mKeyError[0m                                  Traceback (most recent call last)
[0;32m/tmp/ipykernel_1717/3600907280.py[0m in [0;36m<module>[0;34m[0m
[1;32m      3[0m df, meta = pvlib.iotools.get_bsrn(
[1;32m      4[0m     [0mstation[0m[0;34m=[0m[0;34m'cab'[0m[0;34m,[0m [0mstart[0m[0;34m=[0m[0mpd[0m[0;34m.[0m[0mTimestamp[0m[0;34m([0m[0;36m2018[0m[0;34m,[0m[0;36m6[0m[0;34m,[0m[0;36m1[0m[0;34m)[0m[0;34m,[0m [0mend[0m[0;34m=[0m[0mpd[0m[0;34m.[0m[0mTimestamp[0m[0;34m([0m[0;36m2018[0m[0;34m,[0m[0;36m8[0m[0;34m,[0m[0;36m31[0m[0;34m)[0m[0;34m,[0m[0;34m[0m[0;34m[0m[0m
[0;32m----> 5[0;31m     username=BSRN_USERNAME, password=BSRN_PASSWORD)
[0m[1;32m      6[0m [0;34m[0m[0m

[0;32m/opt/hostedtoolcache/Python/3.7.11/x64/lib/python3.7/site-packages/pvlib/iotools/bsrn.py[0m in [0;36mget_bsrn[0;34m(start, end, station, username, password, logical_records, local_path)[0m
[1;32m    167[0m             raise KeyError('Station sub-directory does not exist. Specified '
[1;32m    168[0m                            [0;34m'station is probably not a proper three letter '[0m[0;34m[0m[0;34m[0m[0m
[0;32m--> 169[0;31m                            'station abbreviation.') from e
[0m[1;32m    170[0m         [0mdfs[0m [0;34m=[0m [0;34m[[0m[0;34m][0m  [0;31m# Initialize list for monthly dataframes[0m[0;34m[0m[0;34m[0m[0m
[1;32m    171[0m         [0mnon_existing_files[0m [0;34m=[0m [0;34m[[0m[0;34m][0m  [0;31m# Initilize list of files that were not found[0m[0;34m[0m[0;34m[0m[0m

[0;31mKeyError[0m: 'Station sub-directory does not exist. Specified station is probably not a proper three letter station abbreviation.'
KeyError: 'Station sub-directory does not exist. Specified station is probably not a proper three letter station abbreviation.'

