Traceback (most recent call last):
  File "/opt/hostedtoolcache/Python/3.7.11/x64/lib/python3.7/site-packages/jupyter_cache/executors/utils.py", line 56, in single_nb_execution
    record_timing=False,
  File "/opt/hostedtoolcache/Python/3.7.11/x64/lib/python3.7/site-packages/nbclient/client.py", line 1112, in execute
    return NotebookClient(nb=nb, resources=resources, km=km, **kwargs).execute()
  File "/opt/hostedtoolcache/Python/3.7.11/x64/lib/python3.7/site-packages/nbclient/util.py", line 74, in wrapped
    return just_run(coro(*args, **kwargs))
  File "/opt/hostedtoolcache/Python/3.7.11/x64/lib/python3.7/site-packages/nbclient/util.py", line 53, in just_run
    return loop.run_until_complete(coro)
  File "/opt/hostedtoolcache/Python/3.7.11/x64/lib/python3.7/asyncio/base_events.py", line 587, in run_until_complete
    return future.result()
  File "/opt/hostedtoolcache/Python/3.7.11/x64/lib/python3.7/site-packages/nbclient/client.py", line 554, in async_execute
    cell, index, execution_count=self.code_cells_executed + 1
  File "/opt/hostedtoolcache/Python/3.7.11/x64/lib/python3.7/site-packages/nbclient/client.py", line 857, in async_execute_cell
    self._check_raise_for_error(cell, exec_reply)
  File "/opt/hostedtoolcache/Python/3.7.11/x64/lib/python3.7/site-packages/nbclient/client.py", line 760, in _check_raise_for_error
    raise CellExecutionError.from_cell_and_msg(cell, exec_reply_content)
nbclient.exceptions.CellExecutionError: An error occurred while executing the following cell:
------------------
os.environ['BSRN_FTP_USERNAME']

------------------

[0;31m---------------------------------------------------------------------------[0m
[0;31mKeyError[0m                                  Traceback (most recent call last)
[0;32m/tmp/ipykernel_1676/1514689784.py[0m in [0;36m<module>[0;34m[0m
[0;32m----> 1[0;31m [0mos[0m[0;34m.[0m[0menviron[0m[0;34m[[0m[0;34m'BSRN_FTP_USERNAME'[0m[0;34m][0m[0;34m[0m[0;34m[0m[0m
[0m
[0;32m/opt/hostedtoolcache/Python/3.7.11/x64/lib/python3.7/os.py[0m in [0;36m__getitem__[0;34m(self, key)[0m
[1;32m    679[0m         [0;32mexcept[0m [0mKeyError[0m[0;34m:[0m[0;34m[0m[0;34m[0m[0m
[1;32m    680[0m             [0;31m# raise KeyError with the original key value[0m[0;34m[0m[0;34m[0m[0;34m[0m[0m
[0;32m--> 681[0;31m             [0;32mraise[0m [0mKeyError[0m[0;34m([0m[0mkey[0m[0;34m)[0m [0;32mfrom[0m [0;32mNone[0m[0;34m[0m[0;34m[0m[0m
[0m[1;32m    682[0m         [0;32mreturn[0m [0mself[0m[0;34m.[0m[0mdecodevalue[0m[0;34m([0m[0mvalue[0m[0;34m)[0m[0;34m[0m[0;34m[0m[0m
[1;32m    683[0m [0;34m[0m[0m

[0;31mKeyError[0m: 'BSRN_FTP_USERNAME'
KeyError: 'BSRN_FTP_USERNAME'

